[2023-02-23T04:50:55.109+0000] {taskinstance.py:1083} INFO - Dependencies all met for <TaskInstance: database_dag.initialize_db manual__2023-02-23T04:50:53.543652+00:00 [queued]>
[2023-02-23T04:50:55.120+0000] {taskinstance.py:1083} INFO - Dependencies all met for <TaskInstance: database_dag.initialize_db manual__2023-02-23T04:50:53.543652+00:00 [queued]>
[2023-02-23T04:50:55.124+0000] {taskinstance.py:1279} INFO - 
--------------------------------------------------------------------------------
[2023-02-23T04:50:55.125+0000] {taskinstance.py:1280} INFO - Starting attempt 1 of 2
[2023-02-23T04:50:55.126+0000] {taskinstance.py:1281} INFO - 
--------------------------------------------------------------------------------
[2023-02-23T04:50:55.135+0000] {taskinstance.py:1300} INFO - Executing <Task(PythonOperator): initialize_db> on 2023-02-23 04:50:53.543652+00:00
[2023-02-23T04:50:55.158+0000] {standard_task_runner.py:55} INFO - Started process 21992 to run task
[2023-02-23T04:50:55.164+0000] {standard_task_runner.py:82} INFO - Running: ['***', 'tasks', 'run', 'database_dag', 'initialize_db', 'manual__2023-02-23T04:50:53.543652+00:00', '--job-id', '59', '--raw', '--subdir', 'DAGS_FOLDER/metadataScrapper.py', '--cfg-path', '/tmp/tmpue488kam']
[2023-02-23T04:50:55.168+0000] {standard_task_runner.py:83} INFO - Job 59: Subtask initialize_db
[2023-02-23T04:50:55.244+0000] {task_command.py:388} INFO - Running <TaskInstance: database_dag.initialize_db manual__2023-02-23T04:50:53.543652+00:00 [running]> on host fd37b4f3bb6b
[2023-02-23T04:50:55.312+0000] {taskinstance.py:1509} INFO - Exporting the following env vars:
AIRFLOW_CTX_DAG_OWNER=Charu Singh
AIRFLOW_CTX_DAG_ID=database_dag
AIRFLOW_CTX_TASK_ID=initialize_db
AIRFLOW_CTX_EXECUTION_DATE=2023-02-23T04:50:53.543652+00:00
AIRFLOW_CTX_TRY_NUMBER=1
AIRFLOW_CTX_DAG_RUN_ID=manual__2023-02-23T04:50:53.543652+00:00
[2023-02-23T04:50:55.314+0000] {logging_mixin.py:137} INFO - /opt/***/dags
[2023-02-23T04:50:55.323+0000] {taskinstance.py:1768} ERROR - Task failed with exception
Traceback (most recent call last):
  File "/home/airflow/.local/lib/python3.7/site-packages/airflow/operators/python.py", line 175, in execute
    return_value = self.execute_callable()
  File "/home/airflow/.local/lib/python3.7/site-packages/airflow/operators/python.py", line 192, in execute_callable
    return self.python_callable(*self.op_args, **self.op_kwargs)
  File "/opt/airflow/dags/metadataScrapper.py", line 94, in check_database_initilization
    create_table_in_db()
  File "/opt/airflow/dags/metadataScrapper.py", line 74, in create_table_in_db
    df = create_df()
  File "/opt/airflow/dags/metadataScrapper.py", line 64, in create_df
    data = get_meta_data_for_db_population()
  File "/opt/airflow/dags/metadataScrapper.py", line 127, in get_meta_data_for_db_population
    files = get_files_from_goes_bucket("ABI-L1b-RadC")
  File "/opt/airflow/dags/metadataScrapper.py", line 112, in get_files_from_goes_bucket
    aws_secret_access_key=os.environ.get('AWS_SECRET_KEY'))
TypeError: __init__() got multiple values for argument 'aws_access_key_id'
[2023-02-23T04:50:55.335+0000] {taskinstance.py:1323} INFO - Marking task as UP_FOR_RETRY. dag_id=database_dag, task_id=initialize_db, execution_date=20230223T045053, start_date=20230223T045055, end_date=20230223T045055
[2023-02-23T04:50:55.345+0000] {standard_task_runner.py:105} ERROR - Failed to execute job 59 for task initialize_db (__init__() got multiple values for argument 'aws_access_key_id'; 21992)
[2023-02-23T04:50:55.377+0000] {local_task_job.py:208} INFO - Task exited with return code 1
[2023-02-23T04:50:55.416+0000] {taskinstance.py:2578} INFO - 0 downstream tasks scheduled from follow-on schedule check
