[2023-02-23T22:26:52.851+0000] {taskinstance.py:1083} INFO - Dependencies all met for <TaskInstance: metadata_scraper.scrape_goes_data manual__2023-02-23T22:26:50.708634+00:00 [queued]>
[2023-02-23T22:26:52.861+0000] {taskinstance.py:1083} INFO - Dependencies all met for <TaskInstance: metadata_scraper.scrape_goes_data manual__2023-02-23T22:26:50.708634+00:00 [queued]>
[2023-02-23T22:26:52.862+0000] {taskinstance.py:1279} INFO - 
--------------------------------------------------------------------------------
[2023-02-23T22:26:52.862+0000] {taskinstance.py:1280} INFO - Starting attempt 1 of 1
[2023-02-23T22:26:52.863+0000] {taskinstance.py:1281} INFO - 
--------------------------------------------------------------------------------
[2023-02-23T22:26:52.871+0000] {taskinstance.py:1300} INFO - Executing <Task(PythonOperator): scrape_goes_data> on 2023-02-23 22:26:50.708634+00:00
[2023-02-23T22:26:52.880+0000] {standard_task_runner.py:55} INFO - Started process 2149 to run task
[2023-02-23T22:26:52.885+0000] {standard_task_runner.py:82} INFO - Running: ['***', 'tasks', 'run', 'metadata_scraper', 'scrape_goes_data', 'manual__2023-02-23T22:26:50.708634+00:00', '--job-id', '6', '--raw', '--subdir', 'DAGS_FOLDER/metadataScrapper.py', '--cfg-path', '/tmp/tmpj8x9fzah']
[2023-02-23T22:26:52.886+0000] {standard_task_runner.py:83} INFO - Job 6: Subtask scrape_goes_data
[2023-02-23T22:26:52.975+0000] {task_command.py:388} INFO - Running <TaskInstance: metadata_scraper.scrape_goes_data manual__2023-02-23T22:26:50.708634+00:00 [running]> on host e71d177a0fdc
[2023-02-23T22:26:53.033+0000] {taskinstance.py:1509} INFO - Exporting the following env vars:
AIRFLOW_CTX_DAG_OWNER=Charu Singh
AIRFLOW_CTX_DAG_ID=metadata_scraper
AIRFLOW_CTX_TASK_ID=scrape_goes_data
AIRFLOW_CTX_EXECUTION_DATE=2023-02-23T22:26:50.708634+00:00
AIRFLOW_CTX_TRY_NUMBER=1
AIRFLOW_CTX_DAG_RUN_ID=manual__2023-02-23T22:26:50.708634+00:00
[2023-02-23T22:26:53.407+0000] {taskinstance.py:1768} ERROR - Task failed with exception
Traceback (most recent call last):
  File "/home/airflow/.local/lib/python3.7/site-packages/airflow/operators/python.py", line 175, in execute
    return_value = self.execute_callable()
  File "/home/airflow/.local/lib/python3.7/site-packages/airflow/operators/python.py", line 192, in execute_callable
    return self.python_callable(*self.op_args, **self.op_kwargs)
  File "/opt/airflow/dags/metadataScrapper.py", line 38, in GOES_scrap_load
    Prefix=prefix, Delimiter=delimiter)
  File "/home/airflow/.local/lib/python3.7/site-packages/botocore/client.py", line 530, in _api_call
    return self._make_api_call(operation_name, kwargs)
  File "/home/airflow/.local/lib/python3.7/site-packages/botocore/client.py", line 960, in _make_api_call
    raise error_class(parsed_response, operation_name)
botocore.exceptions.ClientError: An error occurred (InvalidAccessKeyId) when calling the ListObjects operation: The AWS Access Key Id you provided does not exist in our records.
[2023-02-23T22:26:53.423+0000] {taskinstance.py:1323} INFO - Marking task as FAILED. dag_id=metadata_scraper, task_id=scrape_goes_data, execution_date=20230223T222650, start_date=20230223T222652, end_date=20230223T222653
[2023-02-23T22:26:53.437+0000] {standard_task_runner.py:105} ERROR - Failed to execute job 6 for task scrape_goes_data (An error occurred (InvalidAccessKeyId) when calling the ListObjects operation: The AWS Access Key Id you provided does not exist in our records.; 2149)
[2023-02-23T22:26:53.462+0000] {local_task_job.py:208} INFO - Task exited with return code 1
[2023-02-23T22:26:53.490+0000] {taskinstance.py:2578} INFO - 0 downstream tasks scheduled from follow-on schedule check
