[2023-03-02T00:47:13.230+0000] {taskinstance.py:1083} INFO - Dependencies all met for <TaskInstance: metadata_scraper.scrape_goes_data manual__2023-03-02T00:47:10.917372+00:00 [queued]>
[2023-03-02T00:47:13.237+0000] {taskinstance.py:1083} INFO - Dependencies all met for <TaskInstance: metadata_scraper.scrape_goes_data manual__2023-03-02T00:47:10.917372+00:00 [queued]>
[2023-03-02T00:47:13.238+0000] {taskinstance.py:1279} INFO - 
--------------------------------------------------------------------------------
[2023-03-02T00:47:13.239+0000] {taskinstance.py:1280} INFO - Starting attempt 1 of 1
[2023-03-02T00:47:13.240+0000] {taskinstance.py:1281} INFO - 
--------------------------------------------------------------------------------
[2023-03-02T00:47:13.251+0000] {taskinstance.py:1300} INFO - Executing <Task(PythonOperator): scrape_goes_data> on 2023-03-02 00:47:10.917372+00:00
[2023-03-02T00:47:13.266+0000] {standard_task_runner.py:55} INFO - Started process 751 to run task
[2023-03-02T00:47:13.270+0000] {standard_task_runner.py:82} INFO - Running: ['***', 'tasks', 'run', 'metadata_scraper', 'scrape_goes_data', 'manual__2023-03-02T00:47:10.917372+00:00', '--job-id', '14', '--raw', '--subdir', 'DAGS_FOLDER/scrapper.py', '--cfg-path', '/tmp/tmp24epk7u6']
[2023-03-02T00:47:13.273+0000] {standard_task_runner.py:83} INFO - Job 14: Subtask scrape_goes_data
[2023-03-02T00:47:13.365+0000] {task_command.py:388} INFO - Running <TaskInstance: metadata_scraper.scrape_goes_data manual__2023-03-02T00:47:10.917372+00:00 [running]> on host e05f699ebc35
[2023-03-02T00:47:13.421+0000] {taskinstance.py:1509} INFO - Exporting the following env vars:
AIRFLOW_CTX_DAG_OWNER=Charu Singh
AIRFLOW_CTX_DAG_ID=metadata_scraper
AIRFLOW_CTX_TASK_ID=scrape_goes_data
AIRFLOW_CTX_EXECUTION_DATE=2023-03-02T00:47:10.917372+00:00
AIRFLOW_CTX_TRY_NUMBER=1
AIRFLOW_CTX_DAG_RUN_ID=manual__2023-03-02T00:47:10.917372+00:00
[2023-03-02T00:47:30.858+0000] {taskinstance.py:1768} ERROR - Task failed with exception
Traceback (most recent call last):
  File "/home/airflow/.local/lib/python3.7/site-packages/airflow/operators/python.py", line 175, in execute
    return_value = self.execute_callable()
  File "/home/airflow/.local/lib/python3.7/site-packages/airflow/operators/python.py", line 192, in execute_callable
    return self.python_callable(*self.op_args, **self.op_kwargs)
  File "/opt/airflow/dags/scrapper.py", line 79, in GOES_scrap_load
    (row[0], row[1], row[2], row[4], row[5]))
IndexError: tuple index out of range
[2023-03-02T00:47:30.897+0000] {taskinstance.py:1323} INFO - Marking task as FAILED. dag_id=metadata_scraper, task_id=scrape_goes_data, execution_date=20230302T004710, start_date=20230302T004713, end_date=20230302T004730
[2023-03-02T00:47:30.920+0000] {standard_task_runner.py:105} ERROR - Failed to execute job 14 for task scrape_goes_data (tuple index out of range; 751)
[2023-03-02T00:47:30.980+0000] {local_task_job.py:208} INFO - Task exited with return code 1
[2023-03-02T00:47:31.042+0000] {taskinstance.py:2578} INFO - 0 downstream tasks scheduled from follow-on schedule check
