[2023-03-02T18:56:01.646+0000] {taskinstance.py:1083} INFO - Dependencies all met for <TaskInstance: metadata_scraper.scrape_nexrad_data manual__2023-03-02T18:55:57.624661+00:00 [queued]>
[2023-03-02T18:56:01.659+0000] {taskinstance.py:1083} INFO - Dependencies all met for <TaskInstance: metadata_scraper.scrape_nexrad_data manual__2023-03-02T18:55:57.624661+00:00 [queued]>
[2023-03-02T18:56:01.660+0000] {taskinstance.py:1279} INFO - 
--------------------------------------------------------------------------------
[2023-03-02T18:56:01.661+0000] {taskinstance.py:1280} INFO - Starting attempt 1 of 1
[2023-03-02T18:56:01.662+0000] {taskinstance.py:1281} INFO - 
--------------------------------------------------------------------------------
[2023-03-02T18:56:01.674+0000] {taskinstance.py:1300} INFO - Executing <Task(PythonOperator): scrape_nexrad_data> on 2023-03-02 18:55:57.624661+00:00
[2023-03-02T18:56:01.689+0000] {standard_task_runner.py:55} INFO - Started process 1921 to run task
[2023-03-02T18:56:01.696+0000] {standard_task_runner.py:82} INFO - Running: ['***', 'tasks', 'run', 'metadata_scraper', 'scrape_nexrad_data', 'manual__2023-03-02T18:55:57.624661+00:00', '--job-id', '24', '--raw', '--subdir', 'DAGS_FOLDER/scrapper.py', '--cfg-path', '/tmp/tmpxg5am3fm']
[2023-03-02T18:56:01.698+0000] {standard_task_runner.py:83} INFO - Job 24: Subtask scrape_nexrad_data
[2023-03-02T18:56:01.807+0000] {task_command.py:388} INFO - Running <TaskInstance: metadata_scraper.scrape_nexrad_data manual__2023-03-02T18:55:57.624661+00:00 [running]> on host f6e174e28dc0
[2023-03-02T18:56:01.927+0000] {taskinstance.py:1509} INFO - Exporting the following env vars:
AIRFLOW_CTX_DAG_OWNER=Charu Singh
AIRFLOW_CTX_DAG_ID=metadata_scraper
AIRFLOW_CTX_TASK_ID=scrape_nexrad_data
AIRFLOW_CTX_EXECUTION_DATE=2023-03-02T18:55:57.624661+00:00
AIRFLOW_CTX_TRY_NUMBER=1
AIRFLOW_CTX_DAG_RUN_ID=manual__2023-03-02T18:55:57.624661+00:00
[2023-03-02T18:57:08.305+0000] {local_task_job.py:273} WARNING - State of this instance has been externally set to removed. Terminating instance.
[2023-03-02T18:57:08.323+0000] {process_utils.py:133} INFO - Sending Signals.SIGTERM to group 1921. PIDs of all processes in the group: [1921]
[2023-03-02T18:57:08.325+0000] {process_utils.py:84} INFO - Sending the signal Signals.SIGTERM to group 1921
[2023-03-02T18:57:08.333+0000] {taskinstance.py:1479} ERROR - Received SIGTERM. Terminating subprocesses.
[2023-03-02T18:57:08.342+0000] {taskinstance.py:1768} ERROR - Task failed with exception
Traceback (most recent call last):
  File "/home/airflow/.local/lib/python3.7/site-packages/botocore/httpsession.py", line 464, in send
    chunked=self._chunked(request.headers),
  File "/home/airflow/.local/lib/python3.7/site-packages/urllib3/connectionpool.py", line 710, in urlopen
    chunked=chunked,
  File "/home/airflow/.local/lib/python3.7/site-packages/urllib3/connectionpool.py", line 449, in _make_request
    six.raise_from(e, None)
  File "<string>", line 3, in raise_from
  File "/home/airflow/.local/lib/python3.7/site-packages/urllib3/connectionpool.py", line 444, in _make_request
    httplib_response = conn.getresponse()
  File "/usr/local/lib/python3.7/http/client.py", line 1373, in getresponse
    response.begin()
  File "/usr/local/lib/python3.7/http/client.py", line 319, in begin
    version, status, reason = self._read_status()
  File "/usr/local/lib/python3.7/http/client.py", line 280, in _read_status
    line = str(self.fp.readline(_MAXLINE + 1), "iso-8859-1")
  File "/usr/local/lib/python3.7/socket.py", line 589, in readinto
    return self._sock.recv_into(b)
  File "/usr/local/lib/python3.7/ssl.py", line 1071, in recv_into
    return self.read(nbytes, buffer)
  File "/usr/local/lib/python3.7/ssl.py", line 929, in read
    return self._sslobj.read(len, buffer)
  File "/home/airflow/.local/lib/python3.7/site-packages/airflow/models/taskinstance.py", line 1481, in signal_handler
    raise AirflowException("Task received SIGTERM signal")
airflow.exceptions.AirflowException: Task received SIGTERM signal

During handling of the above exception, another exception occurred:

Traceback (most recent call last):
  File "/home/airflow/.local/lib/python3.7/site-packages/airflow/operators/python.py", line 175, in execute
    return_value = self.execute_callable()
  File "/home/airflow/.local/lib/python3.7/site-packages/airflow/operators/python.py", line 192, in execute_callable
    return self.python_callable(*self.op_args, **self.op_kwargs)
  File "/opt/airflow/dags/scrapper.py", line 119, in NEXRAD_scrap_load
    sub_sub_folder = s3.list_objects(Bucket=nexrad_bucket, Prefix=prefix_new2, Delimiter='/')
  File "/home/airflow/.local/lib/python3.7/site-packages/botocore/client.py", line 530, in _api_call
    return self._make_api_call(operation_name, kwargs)
  File "/home/airflow/.local/lib/python3.7/site-packages/botocore/client.py", line 944, in _make_api_call
    operation_model, request_dict, request_context
  File "/home/airflow/.local/lib/python3.7/site-packages/botocore/client.py", line 966, in _make_request
    return self._endpoint.make_request(operation_model, request_dict)
  File "/home/airflow/.local/lib/python3.7/site-packages/botocore/endpoint.py", line 119, in make_request
    return self._send_request(request_dict, operation_model)
  File "/home/airflow/.local/lib/python3.7/site-packages/botocore/endpoint.py", line 207, in _send_request
    exception,
  File "/home/airflow/.local/lib/python3.7/site-packages/botocore/endpoint.py", line 361, in _needs_retry
    request_dict=request_dict,
  File "/home/airflow/.local/lib/python3.7/site-packages/botocore/hooks.py", line 412, in emit
    return self._emitter.emit(aliased_event_name, **kwargs)
  File "/home/airflow/.local/lib/python3.7/site-packages/botocore/hooks.py", line 256, in emit
    return self._emit(event_name, kwargs)
  File "/home/airflow/.local/lib/python3.7/site-packages/botocore/hooks.py", line 239, in _emit
    response = handler(**kwargs)
  File "/home/airflow/.local/lib/python3.7/site-packages/botocore/retryhandler.py", line 207, in __call__
    if self._checker(**checker_kwargs):
  File "/home/airflow/.local/lib/python3.7/site-packages/botocore/retryhandler.py", line 285, in __call__
    attempt_number, response, caught_exception
  File "/home/airflow/.local/lib/python3.7/site-packages/botocore/retryhandler.py", line 308, in _should_retry
    attempt_number, response, caught_exception
  File "/home/airflow/.local/lib/python3.7/site-packages/botocore/retryhandler.py", line 364, in __call__
    attempt_number, response, caught_exception
  File "/home/airflow/.local/lib/python3.7/site-packages/botocore/retryhandler.py", line 248, in __call__
    attempt_number, caught_exception
  File "/home/airflow/.local/lib/python3.7/site-packages/botocore/retryhandler.py", line 416, in _check_caught_exception
    raise caught_exception
  File "/home/airflow/.local/lib/python3.7/site-packages/botocore/endpoint.py", line 281, in _do_get_response
    http_response = self._send(request)
  File "/home/airflow/.local/lib/python3.7/site-packages/botocore/endpoint.py", line 377, in _send
    return self.http_session.send(request)
  File "/home/airflow/.local/lib/python3.7/site-packages/botocore/httpsession.py", line 500, in send
    raise HTTPClientError(error=e)
botocore.exceptions.HTTPClientError: An HTTP Client raised an unhandled exception: Task received SIGTERM signal
[2023-03-02T18:57:08.431+0000] {taskinstance.py:1323} INFO - Marking task as FAILED. dag_id=metadata_scraper, task_id=scrape_nexrad_data, execution_date=20230302T185557, start_date=20230302T185601, end_date=20230302T185708
[2023-03-02T18:57:08.467+0000] {standard_task_runner.py:105} ERROR - Failed to execute job 24 for task scrape_nexrad_data (An HTTP Client raised an unhandled exception: Task received SIGTERM signal; 1921)
[2023-03-02T18:57:08.548+0000] {process_utils.py:79} INFO - Process psutil.Process(pid=1921, status='terminated', exitcode=1, started='18:56:01') (1921) terminated with exit code 1
