[2023-02-23T04:54:04.047+0000] {taskinstance.py:1083} INFO - Dependencies all met for <TaskInstance: database_dag.initialize_db manual__2023-02-23T04:54:01.271566+00:00 [queued]>
[2023-02-23T04:54:04.057+0000] {taskinstance.py:1083} INFO - Dependencies all met for <TaskInstance: database_dag.initialize_db manual__2023-02-23T04:54:01.271566+00:00 [queued]>
[2023-02-23T04:54:04.058+0000] {taskinstance.py:1279} INFO - 
--------------------------------------------------------------------------------
[2023-02-23T04:54:04.059+0000] {taskinstance.py:1280} INFO - Starting attempt 1 of 1
[2023-02-23T04:54:04.060+0000] {taskinstance.py:1281} INFO - 
--------------------------------------------------------------------------------
[2023-02-23T04:54:04.073+0000] {taskinstance.py:1300} INFO - Executing <Task(PythonOperator): initialize_db> on 2023-02-23 04:54:01.271566+00:00
[2023-02-23T04:54:04.085+0000] {standard_task_runner.py:55} INFO - Started process 22190 to run task
[2023-02-23T04:54:04.095+0000] {standard_task_runner.py:82} INFO - Running: ['***', 'tasks', 'run', 'database_dag', 'initialize_db', 'manual__2023-02-23T04:54:01.271566+00:00', '--job-id', '61', '--raw', '--subdir', 'DAGS_FOLDER/metadataScrapper.py', '--cfg-path', '/tmp/tmpz750jlro']
[2023-02-23T04:54:04.108+0000] {standard_task_runner.py:83} INFO - Job 61: Subtask initialize_db
[2023-02-23T04:54:04.176+0000] {task_command.py:388} INFO - Running <TaskInstance: database_dag.initialize_db manual__2023-02-23T04:54:01.271566+00:00 [running]> on host fd37b4f3bb6b
[2023-02-23T04:54:04.234+0000] {taskinstance.py:1509} INFO - Exporting the following env vars:
AIRFLOW_CTX_DAG_OWNER=Charu Singh
AIRFLOW_CTX_DAG_ID=database_dag
AIRFLOW_CTX_TASK_ID=initialize_db
AIRFLOW_CTX_EXECUTION_DATE=2023-02-23T04:54:01.271566+00:00
AIRFLOW_CTX_TRY_NUMBER=1
AIRFLOW_CTX_DAG_RUN_ID=manual__2023-02-23T04:54:01.271566+00:00
[2023-02-23T04:54:04.236+0000] {logging_mixin.py:137} INFO - /opt/***/dags
[2023-02-23T04:54:04.240+0000] {taskinstance.py:1768} ERROR - Task failed with exception
Traceback (most recent call last):
  File "/home/airflow/.local/lib/python3.7/site-packages/airflow/operators/python.py", line 175, in execute
    return_value = self.execute_callable()
  File "/home/airflow/.local/lib/python3.7/site-packages/airflow/operators/python.py", line 192, in execute_callable
    return self.python_callable(*self.op_args, **self.op_kwargs)
  File "/opt/airflow/dags/metadataScrapper.py", line 90, in check_database_initilization
    create_table_in_db()
  File "/opt/airflow/dags/metadataScrapper.py", line 70, in create_table_in_db
    df = create_df()
  File "/opt/airflow/dags/metadataScrapper.py", line 60, in create_df
    data = get_meta_data_for_db_population()
  File "/opt/airflow/dags/metadataScrapper.py", line 123, in get_meta_data_for_db_population
    files = get_files_from_goes_bucket("ABI-L1b-RadC")
  File "/opt/airflow/dags/metadataScrapper.py", line 108, in get_files_from_goes_bucket
    aws_secret_access_key=os.environ.get('AWS_SECRET_KEY'))
TypeError: __init__() got multiple values for argument 'aws_access_key_id'
[2023-02-23T04:54:04.252+0000] {taskinstance.py:1323} INFO - Marking task as FAILED. dag_id=database_dag, task_id=initialize_db, execution_date=20230223T045401, start_date=20230223T045404, end_date=20230223T045404
[2023-02-23T04:54:04.262+0000] {standard_task_runner.py:105} ERROR - Failed to execute job 61 for task initialize_db (__init__() got multiple values for argument 'aws_access_key_id'; 22190)
[2023-02-23T04:54:04.307+0000] {local_task_job.py:208} INFO - Task exited with return code 1
[2023-02-23T04:54:04.327+0000] {taskinstance.py:2578} INFO - 0 downstream tasks scheduled from follow-on schedule check
