[2023-03-02T00:21:17.975+0000] {taskinstance.py:1083} INFO - Dependencies all met for <TaskInstance: metadata_scraper.scrape_goes_data scheduled__2023-02-26T00:00:00+00:00 [queued]>
[2023-03-02T00:21:18.144+0000] {taskinstance.py:1083} INFO - Dependencies all met for <TaskInstance: metadata_scraper.scrape_goes_data scheduled__2023-02-26T00:00:00+00:00 [queued]>
[2023-03-02T00:21:18.148+0000] {taskinstance.py:1279} INFO - 
--------------------------------------------------------------------------------
[2023-03-02T00:21:18.158+0000] {taskinstance.py:1280} INFO - Starting attempt 1 of 1
[2023-03-02T00:21:18.161+0000] {taskinstance.py:1281} INFO - 
--------------------------------------------------------------------------------
[2023-03-02T00:21:18.370+0000] {taskinstance.py:1300} INFO - Executing <Task(PythonOperator): scrape_goes_data> on 2023-02-26 00:00:00+00:00
[2023-03-02T00:21:18.621+0000] {standard_task_runner.py:55} INFO - Started process 1953 to run task
[2023-03-02T00:21:19.030+0000] {standard_task_runner.py:82} INFO - Running: ['***', 'tasks', 'run', 'metadata_scraper', 'scrape_goes_data', 'scheduled__2023-02-26T00:00:00+00:00', '--job-id', '8', '--raw', '--subdir', 'DAGS_FOLDER/scrapper.py', '--cfg-path', '/tmp/tmp5p8lcm6l']
[2023-03-02T00:21:19.385+0000] {standard_task_runner.py:83} INFO - Job 8: Subtask scrape_goes_data
[2023-03-02T00:21:28.194+0000] {task_command.py:388} INFO - Running <TaskInstance: metadata_scraper.scrape_goes_data scheduled__2023-02-26T00:00:00+00:00 [running]> on host 03892a27b5ab
[2023-03-02T00:22:20.701+0000] {taskinstance.py:1509} INFO - Exporting the following env vars:
AIRFLOW_CTX_DAG_OWNER=Charu Singh
AIRFLOW_CTX_DAG_ID=metadata_scraper
AIRFLOW_CTX_TASK_ID=scrape_goes_data
AIRFLOW_CTX_EXECUTION_DATE=2023-02-26T00:00:00+00:00
AIRFLOW_CTX_TRY_NUMBER=1
AIRFLOW_CTX_DAG_RUN_ID=scheduled__2023-02-26T00:00:00+00:00
[2023-03-02T00:22:21.815+0000] {taskinstance.py:1768} ERROR - Task failed with exception
Traceback (most recent call last):
  File "/home/airflow/.local/lib/python3.7/site-packages/airflow/operators/python.py", line 175, in execute
    return_value = self.execute_callable()
  File "/home/airflow/.local/lib/python3.7/site-packages/airflow/operators/python.py", line 192, in execute_callable
    return self.python_callable(*self.op_args, **self.op_kwargs)
  File "/opt/airflow/dags/scrapper.py", line 38, in GOES_scrap_load
    result = s3.list_objects(Bucket=goes_bucket, Prefix=prefix, Delimiter='/')
  File "/home/airflow/.local/lib/python3.7/site-packages/botocore/client.py", line 530, in _api_call
    return self._make_api_call(operation_name, kwargs)
  File "/home/airflow/.local/lib/python3.7/site-packages/botocore/client.py", line 944, in _make_api_call
    operation_model, request_dict, request_context
  File "/home/airflow/.local/lib/python3.7/site-packages/botocore/client.py", line 966, in _make_request
    return self._endpoint.make_request(operation_model, request_dict)
  File "/home/airflow/.local/lib/python3.7/site-packages/botocore/endpoint.py", line 119, in make_request
    return self._send_request(request_dict, operation_model)
  File "/home/airflow/.local/lib/python3.7/site-packages/botocore/endpoint.py", line 198, in _send_request
    request = self.create_request(request_dict, operation_model)
  File "/home/airflow/.local/lib/python3.7/site-packages/botocore/endpoint.py", line 137, in create_request
    operation_name=operation_model.name,
  File "/home/airflow/.local/lib/python3.7/site-packages/botocore/hooks.py", line 412, in emit
    return self._emitter.emit(aliased_event_name, **kwargs)
  File "/home/airflow/.local/lib/python3.7/site-packages/botocore/hooks.py", line 256, in emit
    return self._emit(event_name, kwargs)
  File "/home/airflow/.local/lib/python3.7/site-packages/botocore/hooks.py", line 239, in _emit
    response = handler(**kwargs)
  File "/home/airflow/.local/lib/python3.7/site-packages/botocore/signers.py", line 105, in handler
    return self.sign(operation_name, request)
  File "/home/airflow/.local/lib/python3.7/site-packages/botocore/signers.py", line 189, in sign
    auth.add_auth(request)
  File "/home/airflow/.local/lib/python3.7/site-packages/botocore/auth.py", line 418, in add_auth
    raise NoCredentialsError()
botocore.exceptions.NoCredentialsError: Unable to locate credentials
[2023-03-02T00:22:24.684+0000] {taskinstance.py:1323} INFO - Marking task as FAILED. dag_id=metadata_scraper, task_id=scrape_goes_data, execution_date=20230226T000000, start_date=20230302T002118, end_date=20230302T002223
[2023-03-02T00:22:31.847+0000] {standard_task_runner.py:105} ERROR - Failed to execute job 8 for task scrape_goes_data (Unable to locate credentials; 1953)
[2023-03-02T00:23:01.966+0000] {local_task_job.py:273} WARNING - State of this instance has been externally set to failed. Terminating instance.
[2023-03-02T00:23:02.916+0000] {process_utils.py:133} INFO - Sending Signals.SIGTERM to group 1953. PIDs of all processes in the group: [1953]
[2023-03-02T00:23:03.837+0000] {process_utils.py:84} INFO - Sending the signal Signals.SIGTERM to group 1953
[2023-03-02T00:23:11.715+0000] {process_utils.py:79} INFO - Process psutil.Process(pid=1953, status='terminated', exitcode=1, started='00:21:17') (1953) terminated with exit code 1
