[2023-02-23T23:07:06.186+0000] {taskinstance.py:1083} INFO - Dependencies all met for <TaskInstance: database_to_csv.export_to_csv manual__2023-02-23T23:07:03.736756+00:00 [queued]>
[2023-02-23T23:07:06.199+0000] {taskinstance.py:1083} INFO - Dependencies all met for <TaskInstance: database_to_csv.export_to_csv manual__2023-02-23T23:07:03.736756+00:00 [queued]>
[2023-02-23T23:07:06.204+0000] {taskinstance.py:1279} INFO - 
--------------------------------------------------------------------------------
[2023-02-23T23:07:06.206+0000] {taskinstance.py:1280} INFO - Starting attempt 1 of 1
[2023-02-23T23:07:06.210+0000] {taskinstance.py:1281} INFO - 
--------------------------------------------------------------------------------
[2023-02-23T23:07:06.227+0000] {taskinstance.py:1300} INFO - Executing <Task(PythonOperator): export_to_csv> on 2023-02-23 23:07:03.736756+00:00
[2023-02-23T23:07:06.235+0000] {standard_task_runner.py:55} INFO - Started process 4627 to run task
[2023-02-23T23:07:06.240+0000] {standard_task_runner.py:82} INFO - Running: ['***', 'tasks', 'run', 'database_to_csv', 'export_to_csv', 'manual__2023-02-23T23:07:03.736756+00:00', '--job-id', '17', '--raw', '--subdir', 'DAGS_FOLDER/metadataScrapper.py', '--cfg-path', '/tmp/tmpm8pq0lz1']
[2023-02-23T23:07:06.242+0000] {standard_task_runner.py:83} INFO - Job 17: Subtask export_to_csv
[2023-02-23T23:07:06.312+0000] {task_command.py:388} INFO - Running <TaskInstance: database_to_csv.export_to_csv manual__2023-02-23T23:07:03.736756+00:00 [running]> on host e71d177a0fdc
[2023-02-23T23:07:06.373+0000] {taskinstance.py:1509} INFO - Exporting the following env vars:
AIRFLOW_CTX_DAG_OWNER=Charu Singh
AIRFLOW_CTX_DAG_ID=database_to_csv
AIRFLOW_CTX_TASK_ID=export_to_csv
AIRFLOW_CTX_EXECUTION_DATE=2023-02-23T23:07:03.736756+00:00
AIRFLOW_CTX_TRY_NUMBER=1
AIRFLOW_CTX_DAG_RUN_ID=manual__2023-02-23T23:07:03.736756+00:00
[2023-02-23T23:07:06.396+0000] {taskinstance.py:1768} ERROR - Task failed with exception
Traceback (most recent call last):
  File "/home/airflow/.local/lib/python3.7/site-packages/airflow/operators/python.py", line 175, in execute
    return_value = self.execute_callable()
  File "/home/airflow/.local/lib/python3.7/site-packages/airflow/operators/python.py", line 192, in execute_callable
    return self.python_callable(*self.op_args, **self.op_kwargs)
  File "/opt/airflow/dags/metadataScrapper.py", line 149, in database_to_csv
    cur.execute("SELECT * FROM metadata_goes18")
sqlite3.OperationalError: no such table: metadata_goes18
[2023-02-23T23:07:06.411+0000] {taskinstance.py:1323} INFO - Marking task as FAILED. dag_id=database_to_csv, task_id=export_to_csv, execution_date=20230223T230703, start_date=20230223T230706, end_date=20230223T230706
[2023-02-23T23:07:06.429+0000] {standard_task_runner.py:105} ERROR - Failed to execute job 17 for task export_to_csv (no such table: metadata_goes18; 4627)
[2023-02-23T23:07:06.455+0000] {local_task_job.py:208} INFO - Task exited with return code 1
[2023-02-23T23:07:06.485+0000] {taskinstance.py:2578} INFO - 0 downstream tasks scheduled from follow-on schedule check
